Workbook

Sheet Data
A1: ITEM | B1: PROBLEMA | C1: QUE (NECESIDAD) | D1: PARA QUE (SOLUCIÓN) | E1: PARA QUIEN (USUARIO) | F1: COMO (DESCRIPCIÓN DE TAREAS) | G1: HECHO POR (PROG. RESP.) | H1: CUANTO TIEMPO (ESTIMADO EN HRS) | I1: FECHA DE ENTREGA | J1: PRIORIDAD | K1: STATUS | L1: PRUEBA (COMO SE VERIFICA) | M1: COMENTARIOS | N1: NOMBRE DE HISTORIA
A2: REQ001 | B2: El sistema debe permitir registrar productos nuevos | C2: Registrar nombre, precios, país de origen, stock e imagen del producto | D2: Gestionar el inventario y controlar productos disponibles | E2: Propietario | F2: Ingresar datos del producto en formulario, el sistema genera código automático y valida información antes de guardar | G2: Leonardo Narvaez | H2: 4 | I2: 46056 | J2: Alta | K2: No iniciado | L2: Validar campos obligatorios, rangos de precios (0.01-99.99), stock mayor a 0. Verificar código único generado y mensaje de confirmación. | M2: Códigos de producto no se reutilizan al eliminar | N2: Registrar Producto
A3: REQ002 | B3: El sistema debe permitir actualizar datos de productos registrados | C3: Modificar nombre, precios, país, stock o imagen de productos existentes | D3: Mantener actualizada la información del inventario | E3: Propietario | F3: Seleccionar producto de lista, editar campos en formulario y guardar cambios validados | G3: Caetano Flores | H3: 2 | I3: 46056 | J3: Alta | K3: No iniciado | L3: Validar que actualización cumpla mismas reglas que registro. Stock no puede ser negativo. Mensaje de confirmación al actualizar. | M3: Permite incrementos y decrementos de stock con validaciones | N3: Actualizar Producto
A4: REQ003 | B4: El sistema debe permitir consultar información de productos | C4: Buscar productos por nombre o código y visualizar su información completa | D4: Revisar disponibilidad y detalles de productos registrados | E4: Propietario | F4: Ingresar criterio de búsqueda (nombre o código), sistema muestra resultados coincidentes | G4: AnthonyMorales | H4: 3 | I4: 46056 | J4: Alta | K4: No iniciado | L4: Búsqueda por código exacto muestra un producto. Búsqueda por nombre muestra coincidencias parciales. Mensaje si no hay resultados. | M4: Búsqueda por código prioritaria si tiene formato letra+dígitos | N4: Consultar Producto
A5: REQ004 | B5: El sistema debe permitir desactivar productos | C5: Marcar productos como inactivos sin eliminarlos físicamente | D5: Mantener historial y evitar uso en nuevas transacciones | E5: Propietario | F5: Seleccionar producto, confirmar eliminación, sistema actualiza estado a Inactivo | G5: AnthonyMorales | H5: 2 | I5: 46056 | J5: Alta | K5: No iniciado | L5: Producto marcado como Inactivo no aparece en selecciones futuras pero conserva historial. Confirmación de desactivación exitosa. | M5: Código del producto no se libera para reutilización | N5: Eliminar Producto
A6: REQ005 | B6: El sistema debe permitir registrar pedidos nuevos | C6: Asociar cliente, productos, cantidades y calcular totales del pedido | D6: Gestionar ventas y controlar inventario | E6: Propietario | F6: Seleccionar cliente y productos, especificar cantidades, sistema calcula totales y guarda pedido | G6: Leonardo Narvaez | H6: 3 | I6: 46056 | J6: Alta | K6: No iniciado | L6: Validar cliente seleccionado, productos con cantidad mayor a 0, stock disponible, formato de fecha DD/MM/AAAA. Confirmación y ID único generado. | M6: Fecha auto-completada con fecha actual pero editable | N6: Registrar Pedido
A7: REQ006 | B7: El sistema debe permitir consultar información de pedidos | C7: Buscar y visualizar detalles de pedidos por filtros | D7: Revisar historial y estado de pedidos | E7: Propietario | F7: Aplicar filtros (ID, cliente, fechas, estado), sistema muestra resultados | G7: Jordan Guaman | H7: 2 | I7: 46056 | J7: Alta | K7: No iniciado | L7: Filtros funcionan correctamente. Visualización completa de información del pedido. Mensaje si no hay resultados. | M7: Interfaz intuitiva para filtrado | N7: Consultar Pedido
A8: REQ007 | B8: El sistema debe permitir eliminar pedidos | C8: Cancelar pedidos y revertir cambios en inventario | D8: Anular pedidos incorrectos y restaurar stock | E8: Propietario | F8: Seleccionar pedido, confirmar eliminación, actualizar estado a Cancelado y revertir stock | G8: AnthonyMorales | H8: 2 | I8: 46056 | J8: Alta | K8: No iniciado | L8: Pedido marcado como Cancelado. Stock revertido correctamente. Historial conservado. Mensaje de confirmación. | M8: Eliminación lógica que conserva historial | N8: Eliminar Pedido
A9: REQ008 | B9: El sistema debe permitir consultar información de clientes | C9: Buscar clientes por nombre o identificación | D9: Revisar información de clientes registrados | E9: Propietario | F9: Ingresar criterio de búsqueda, sistema muestra resultados coincidentes | G9: Caetano Flores | H9: 1 | I9: 46056 | J9: Media | K9: No iniciado | L9: Búsqueda exacta o parcial muestra clientes coincidentes. Mensaje si no hay resultados. | N9: Consultar Cliente
A10: REQ009 | B10: El sistema debe permitir registrar clientes nuevos | C10: Registrar nombre, identificación, correo, teléfono y dirección del cliente | D10: Gestionar información de clientes y asociarlos a pedidos | E10: Propietario | F10: Ingresar datos del cliente en formulario, validar formatos y guardar en base de datos | G10: Leonardo Narvaez | H10: 3 | I10: 46056 | J10: Baja | K10: No iniciado | L10: Validar campos obligatorios, formato de cédula/RUC/pasaporte, email y teléfono válidos. Identificación única. Mensaje de confirmación. | M10: Todos los campos son obligatorios | N10: Registrar Cliente
A11: REQ010 | B11: El sistema debe permitir actualizar datos de clientes | C11: Modificar información de clientes registrados | D11: Mantener datos de clientes actualizados | E11: Propietario | F11: Seleccionar cliente de lista, editar campos y guardar cambios validados | G11: Caetano Flores | H11: 2 | I11: 46056 | J11: Baja | K11: No iniciado | L11: Validar mismas reglas que registro. Verificar formatos de identificación, email y teléfono. Mensaje de confirmación. | N11: Actualizar Cliente
A12: REQ011 | B12: El sistema debe permitir desactivar clientes | C12: Marcar clientes como inactivos lógicamente | D12: Excluirlos de nuevas selecciones pero mantener historial | E12: Propietario | F12: Seleccionar cliente, confirmar eliminación, actualizar estado a Inactivo | G12: Caetano Flores | H12: 1 | I12: 46056 | J12: Baja | K12: No iniciado | L12: Cliente marcado Inactivo no disponible para nuevos pedidos. Historial se conserva. Mensaje de confirmación. | M12: Puede alternarse vista entre clientes Activos e Inactivos | N12: Eliminar Cliente
A13: REQ012 | B13: El sistema debe permitir actualizar pedidos existentes | C13: Modificar cliente o productos de un pedido registrado | D13: Corregir errores o ajustar pedidos antes de completarlos | E13: Propietario | F13: Seleccionar pedido, editar datos, sistema recalcula totales y actualiza inventario | G13: AnthonyMorales | H13: 3 | I13: 46056 | J13: Baja | K13: No iniciado | L13: Validar cliente y productos válidos, stock disponible para aumentos. Recalculo correcto de totales. Mensaje de confirmación. | M13: Ajusta inventario por aumentos o disminuciones de cantidades | N13: Actualizar Pedido
A14: REQ013 | B14: El sistema debe permitir controlar el estado de pedidos | C14: Actualizar estado del pedido según avance | D14: Seguimiento del proceso de cada pedido | E14: Propietario | F14: Seleccionar pedido, elegir nuevo estado de opciones permitidas, actualizar | G14: Leonardo Narvaez | H14: 5 | I14: 46056 | J14: Baja | K14: No iniciado | L14: Validar transiciones permitidas entre estados. No permitir cambios desde Completado o Cancelado. Mensaje de confirmación. | M14: Estados: Pendiente, En Proceso, En Espera, Completado, Cancelado | N14: Controlar Estado de Pedido
A15: REQ014 | B15: El sistema debe permitir generar reportes de pedidos | C15: Exportar datos de pedidos filtrados a archivo Excel | D15: Análisis de ventas y toma de decisiones | E15: Propietario | F15: Aplicar filtros deseados, generar reporte, descargar archivo Excel con información completa | G15: Leonardo Narvaez | H15: 6 | I15: 46056 | J15: Baja | K15: No iniciado | L15: Archivo Excel generado con información correcta según filtros. Incluye datos de pedido, cliente, productos, totales y resúmenes. | M15: Incluye agregados como total de ventas y productos vendidos | N15: Generar Reporte de Pedidos
A16: REQ015 | B16: El sistema debe permitir crear mezclas personalizadas | C16: Seleccionar productos, especificar cantidades y calcular precio total de mezcla | D16: Ofrecer productos personalizados a clientes | E16: Propietario | F16: Seleccionar productos, ingresar cantidades en libras, sistema calcula precio dinámicamente | G16: Jordan Guaman | H16: 5 | I16: 46056 | J16: Baja | K16: No iniciado | L16: Productos añadidos correctamente. Cantidades válidas y stock disponible. Cálculo de precio correcto. Opciones de guardar o agregar a pedido funcionan. | M16: Nombre de mezcla: 3-25 caracteres alfanuméricos | N16: Crear Nueva Mezcla Personalizada
A17: REQ016 | B17: El sistema debe permitir consultar mezclas personalizadas | C17: Visualizar mezclas guardadas y recibir recomendaciones | D17: Reutilizar mezclas y sugerir combinaciones basadas en historial | E17: Propietario | F17: Ver mezclas predefinidas y guardadas, recibir sugerencias, ajustar cantidades | G17: Jordan Guaman | H17: 3 | I17: 46056 | J17: Baja | K17: No iniciado | L17: Mezclas guardadas se muestran correctamente. Recomendaciones basadas en historial. Cálculos dinámicos de precio y nutrición funcionan. | M17: Recomendaciones simples basadas en compras frecuentes | N17: Consultar Mezclas Personalizadas
A18: REQ017 | B18: El sistema debe permitir guardar mezclas personalizadas | C18: Almacenar mezclas diseñadas para uso futuro | D18: Reutilizar combinaciones favoritas en pedidos futuros | E18: Propietario | F18: Diseñar mezcla, ingresar nombre único, guardar en perfil | G18: Jordan Guaman | H18: 2 | I18: 46056 | J18: Baja | K18: No iniciado | L18: Nombre no vacío y no excede 100 caracteres. Mezcla guardada en base de datos. Mensaje de confirmación. | M18: Mezclas guardadas no afectan stock hasta usarse en pedido | N18: Guardar Mezcla Personalizada

Sheet Backlog
A1: ID | B1: Tema | C1: Como un.. | D1: necesito | E1: asi podre... | F1: notas | G1: prioridad | H1: estatus
A2: REQ001 | B2: Consultar Producto | C2: Propietario | D2: Ingresar criterio de búsqueda (nombre o código), sistema muestra resultados coincidentes | E2: Ingresar criterio de búsqueda (nombre o código), sistema muestra resultados coincidentes | F2: Búsqueda por código prioritaria si tiene formato letra+dígitos | G2: Baja | H2: En Proceso
A3: REQ002 | B3: =VLOOKUP(Backlog!A3,Data!$A$2:$N$18,14) -> Actualizar Producto | C3: =VLOOKUP(Backlog!$A3,Data!$A$2:$N$18,5) -> Propietario | D3: =VLOOKUP(Backlog!$A3,Data!$A$2:$N$18,6) -> Seleccionar producto de lista, editar campos en formulario y guardar cambios validados | E3: =VLOOKUP(Backlog!$A3,Data!$A$2:$N$18,6) -> Seleccionar producto de lista, editar campos en formulario y guardar cambios validados | F3: =VLOOKUP(Backlog!$A3,Data!$A$2:$N$18,13) -> Permite incrementos y decrementos de stock con validaciones | G3: Media | H3: En Proceso
A4: REQ003 | B4: =VLOOKUP(Backlog!A2,Data!$A$2:$N$18,14) -> Registrar Producto | C4: =VLOOKUP(Backlog!$A2,Data!$A$2:$N$18,5) -> Propietario | D4: =VLOOKUP(Backlog!$A2,Data!$A$2:$N$18,6) -> Ingresar datos del producto en formulario, el sistema genera código automático y valida información antes de guardar | E4: =VLOOKUP(Backlog!$A2,Data!$A$2:$N$18,6) -> Ingresar datos del producto en formulario, el sistema genera código automático y valida información antes de guardar | F4: =VLOOKUP(Backlog!$A2,Data!$A$2:$N$18,13) -> Códigos de producto no se reutilizan al eliminar | G4: Alta | H4: En Proceso
A5: REQ004 | B5: =VLOOKUP(Backlog!A5,Data!$A$2:$N$18,14) -> Eliminar Producto | C5: =VLOOKUP(Backlog!$A5,Data!$A$2:$N$18,5) -> Propietario | D5: =VLOOKUP(Backlog!$A5,Data!$A$2:$N$18,6) -> Seleccionar producto, confirmar eliminación, sistema actualiza estado a Inactivo | E5: =VLOOKUP(Backlog!$A5,Data!$A$2:$N$18,6) -> Seleccionar producto, confirmar eliminación, sistema actualiza estado a Inactivo | F5: =VLOOKUP(Backlog!$A5,Data!$A$2:$N$18,13) -> Código del producto no se libera para reutilización | G5: Alta | H5: En Proceso
A6: REQ005 | B6: =VLOOKUP(Backlog!A6,Data!$A$2:$N$18,14) -> Registrar Pedido | C6: =VLOOKUP(Backlog!$A6,Data!$A$2:$N$18,5) -> Propietario | D6: =VLOOKUP(Backlog!$A6,Data!$A$2:$N$18,6) -> Seleccionar cliente y productos, especificar cantidades, sistema calcula totales y guarda pedido | E6: =VLOOKUP(Backlog!$A6,Data!$A$2:$N$18,6) -> Seleccionar cliente y productos, especificar cantidades, sistema calcula totales y guarda pedido | F6: =VLOOKUP(Backlog!$A6,Data!$A$2:$N$18,13) -> Fecha auto-completada con fecha actual pero editable | G6: Media | H6: En Proceso
A7: REQ006 | B7: =VLOOKUP(Backlog!A7,Data!$A$2:$N$18,14) -> Consultar Pedido | C7: =VLOOKUP(Backlog!$A7,Data!$A$2:$N$18,5) -> Propietario | D7: =VLOOKUP(Backlog!$A7,Data!$A$2:$N$18,6) -> Aplicar filtros (ID, cliente, fechas, estado), sistema muestra resultados | E7: =VLOOKUP(Backlog!$A7,Data!$A$2:$N$18,6) -> Aplicar filtros (ID, cliente, fechas, estado), sistema muestra resultados | F7: =VLOOKUP(Backlog!$A7,Data!$A$2:$N$18,13) -> Interfaz intuitiva para filtrado | G7: Baja | H7: En Proceso
A8: REQ007 | B8: =VLOOKUP(Backlog!A8,Data!$A$2:$N$18,14) -> Eliminar Pedido | C8: =VLOOKUP(Backlog!$A8,Data!$A$2:$N$18,5) -> Propietario | D8: =VLOOKUP(Backlog!$A8,Data!$A$2:$N$18,6) -> Seleccionar pedido, confirmar eliminación, actualizar estado a Cancelado y revertir stock | E8: =VLOOKUP(Backlog!$A8,Data!$A$2:$N$18,6) -> Seleccionar pedido, confirmar eliminación, actualizar estado a Cancelado y revertir stock | F8: =VLOOKUP(Backlog!$A8,Data!$A$2:$N$18,13) -> Eliminación lógica que conserva historial | G8: Alta | H8: En Proceso
A9: REQ008 | B9: =VLOOKUP(Backlog!A9,Data!$A$2:$N$18,14) -> Consultar Cliente | C9: =VLOOKUP(Backlog!$A9,Data!$A$2:$N$18,5) -> Propietario | D9: =VLOOKUP(Backlog!$A9,Data!$A$2:$N$18,6) -> Ingresar criterio de búsqueda, sistema muestra resultados coincidentes | E9: =VLOOKUP(Backlog!$A9,Data!$A$2:$N$18,6) -> Ingresar criterio de búsqueda, sistema muestra resultados coincidentes | F9: =VLOOKUP(Backlog!$A9,Data!$A$2:$N$18,13) | G9: Media | H9: En Proceso
A10: REQ009 | B10: =VLOOKUP(Backlog!A10,Data!$A$2:$N$18,14) -> Registrar Cliente | C10: =VLOOKUP(Backlog!$A10,Data!$A$2:$N$18,5) -> Propietario | D10: =VLOOKUP(Backlog!$A10,Data!$A$2:$N$18,6) -> Ingresar datos del cliente en formulario, validar formatos y guardar en base de datos | E10: =VLOOKUP(Backlog!$A10,Data!$A$2:$N$18,6) -> Ingresar datos del cliente en formulario, validar formatos y guardar en base de datos | F10: =VLOOKUP(Backlog!$A10,Data!$A$2:$N$18,13) -> Todos los campos son obligatorios | G10: Baja | H10: En Proceso
A11: REQ010 | B11: =VLOOKUP(Backlog!A11,Data!$A$2:$N$18,14) -> Actualizar Cliente | C11: =VLOOKUP(Backlog!$A11,Data!$A$2:$N$18,5) -> Propietario | D11: =VLOOKUP(Backlog!$A11,Data!$A$2:$N$18,6) -> Seleccionar cliente de lista, editar campos y guardar cambios validados | E11: =VLOOKUP(Backlog!$A11,Data!$A$2:$N$18,6) -> Seleccionar cliente de lista, editar campos y guardar cambios validados | F11: =VLOOKUP(Backlog!$A11,Data!$A$2:$N$18,13) | G11: Alta | H11: En Proceso
A12: REQ011 | B12: =VLOOKUP(Backlog!A12,Data!$A$2:$N$18,14) -> Eliminar Cliente | C12: =VLOOKUP(Backlog!$A12,Data!$A$2:$N$18,5) -> Propietario | D12: =VLOOKUP(Backlog!$A12,Data!$A$2:$N$18,6) -> Seleccionar cliente, confirmar eliminación, actualizar estado a Inactivo | E12: =VLOOKUP(Backlog!$A12,Data!$A$2:$N$18,6) -> Seleccionar cliente, confirmar eliminación, actualizar estado a Inactivo | F12: =VLOOKUP(Backlog!$A12,Data!$A$2:$N$18,13) -> Puede alternarse vista entre clientes Activos e Inactivos | G12: Media | H12: En Proceso
A13: REQ012 | B13: =VLOOKUP(Backlog!A13,Data!$A$2:$N$18,14) -> Actualizar Pedido | C13: =VLOOKUP(Backlog!$A13,Data!$A$2:$N$18,5) -> Propietario | D13: =VLOOKUP(Backlog!$A13,Data!$A$2:$N$18,6) -> Seleccionar pedido, editar datos, sistema recalcula totales y actualiza inventario | E13: =VLOOKUP(Backlog!$A13,Data!$A$2:$N$18,6) -> Seleccionar pedido, editar datos, sistema recalcula totales y actualiza inventario | F13: =VLOOKUP(Backlog!$A13,Data!$A$2:$N$18,13) -> Ajusta inventario por aumentos o disminuciones de cantidades | G13: Baja | H13: En Proceso
A14: REQ013 | B14: =VLOOKUP(Backlog!A14,Data!$A$2:$N$18,14) -> Controlar Estado de Pedido | C14: =VLOOKUP(Backlog!$A14,Data!$A$2:$N$18,5) -> Propietario | D14: =VLOOKUP(Backlog!$A14,Data!$A$2:$N$18,6) -> Seleccionar pedido, elegir nuevo estado de opciones permitidas, actualizar | E14: =VLOOKUP(Backlog!$A14,Data!$A$2:$N$18,6) -> Seleccionar pedido, elegir nuevo estado de opciones permitidas, actualizar | F14: =VLOOKUP(Backlog!$A14,Data!$A$2:$N$18,13) -> Estados: Pendiente, En Proceso, En Espera, Completado, Cancelado | G14: Alta | H14: En Proceso
A15: REQ014 | B15: =VLOOKUP(Backlog!A15,Data!$A$2:$N$18,14) -> Generar Reporte de Pedidos | C15: =VLOOKUP(Backlog!$A15,Data!$A$2:$N$18,5) -> Propietario | D15: =VLOOKUP(Backlog!$A15,Data!$A$2:$N$18,6) -> Aplicar filtros deseados, generar reporte, descargar archivo Excel con información completa | E15: =VLOOKUP(Backlog!$A15,Data!$A$2:$N$18,6) -> Aplicar filtros deseados, generar reporte, descargar archivo Excel con información completa | F15: =VLOOKUP(Backlog!$A15,Data!$A$2:$N$18,13) -> Incluye agregados como total de ventas y productos vendidos | G15: Media | H15: En Proceso
A16: REQ015 | B16: =VLOOKUP(Backlog!A16,Data!$A$2:$N$18,14) -> Crear Nueva Mezcla Personalizada | C16: =VLOOKUP(Backlog!$A16,Data!$A$2:$N$18,5) -> Propietario | D16: =VLOOKUP(Backlog!$A16,Data!$A$2:$N$18,6) -> Seleccionar productos, ingresar cantidades en libras, sistema calcula precio dinámicamente | E16: =VLOOKUP(Backlog!$A16,Data!$A$2:$N$18,6) -> Seleccionar productos, ingresar cantidades en libras, sistema calcula precio dinámicamente | F16: =VLOOKUP(Backlog!$A16,Data!$A$2:$N$18,13) -> Nombre de mezcla: 3-25 caracteres alfanuméricos | G16: Baja | H16: En Proceso
... A18: REQ017 | B18: =VLOOKUP(Backlog!A18,Data!$A$2:$N$18,14) -> Guardar Mezcla Personalizada | C18: =VLOOKUP(Backlog!$A18,Data!$A$2:$N$18,5) -> Propietario | D18: =VLOOKUP(Backlog!$A18,Data!$A$2:$N$18,6) -> Diseñar mezcla, ingresar nombre único, guardar en perfil | E18: =VLOOKUP(Backlog!$A18,Data!$A$2:$N$18,6) -> Diseñar mezcla, ingresar nombre único, guardar en perfil | F18: =VLOOKUP(Backlog!$A18,Data!$A$2:$N$18,13) -> Mezclas guardadas no afectan stock hasta usarse en pedido | G18: Media | H18: En Proceso

Sheet sprint0
B3: ID | C3: Tema | D3: Como un.. | E3: Necesito | F3: así podre... | G3: encargado | H3: notas | I3: Prioridad | J3: Status | K3: HORAS
B4: REQ001 | C4: Consultar Producto | D4: Propietario | E4: Ingresar criterio de búsqueda (nombre o código), sistema muestra resultados coincidentes | F4: Ingresar criterio de búsqueda (nombre o código), sistema muestra resultados coincidentes | G4: AnthonyMorales / Jordan Guaman | H4: Búsqueda por código prioritaria si tiene formato letra+dígitos | I4: Baja | J4: En Proceso | K4: =SUM(K5:K7) -> 14
B5: REQ001-1 | C5: Diseño del modelo de datos | E5: Definir la estructura de las tablas, campos, relaciones y restricciones del sistema. | F5: Asegurar que la información se almacene de forma correcta y escalable. | G5: Jordan Guaman | H5: Incluir entidades de productos, categorías y relaciones básicas. Validar normalización. | I5: Alta | J5: En Proceso | K5: 5
B6: REQ001-2 | C6: Implementación de la base de datos en SQLite | E6: Crear físicamente la base de datos usando el modelo definido. | F6: Guardar y consultar datos reales desde la aplicación. | G6: AnthonyMorales | H6: Usar SQLite por ser liviano y portable. Crear scripts de creación. | I6: Alta | J6: En Proceso | K6: 4
B7: REQ001-3 | C7: Desarrollo de la interfaz de listado de productos | E7: Construir una pantalla donde se visualicen los productos. | F7: Mostrar información al usuario de forma clara e interactiva. | G7: AnthonyMorales | H7: Incluir scroll y busqueda | I7: Alta | J7: En Proceso | K7: 5
B8: REQ002 | C8: Actualizar Producto | D8: Propietario | E8: Seleccionar producto de lista, editar campos en formulario y guardar cambios validados | F8: Seleccionar producto de lista, editar campos en formulario y guardar cambios validados | G8: Caetano Flores | H8: Permite incrementos y decrementos de stock con validaciones | I8: Alta | J8: En Proceso | K8: =SUM(K9:K12) -> 10.5
B9: REQ002-1 | C9: Selección de producto desde la lista | E9: Seleccionar un producto desde el listado | F9: Identificar correctamente el producto a modificar | G9: Caetano Flores | H9: Resaltar producto seleccionado | I9: Alta | J9: En Proceso | K9: 2
B10: REQ002-2 | C10: Formulario de edición de producto | E10: Mostrar los datos del producto en un formulario editable | F10: Modificar la información de forma controlada | G10: Caetano Flores | H10: Bloquear edición del código | I10: Alta | J10: En Proceso | K10: 3.5
B11: REQ002-3 | C11: Validación de datos de edición | E11: Validar campos antes de guardar cambios | F11: Evitar errores e inconsistencias | G11: Caetano Flores | H11: Stock no negativo, campos obligatorios | I11: Alta | J11: En Proceso | K11: 2.5
B12: REQ002-4 | C12: Actualización en base de datos | E12: Guardar los cambios del producto editado | F12: Mantener la base de datos actualizada | G12: Caetano Flores | H12: Usar transacciones | I12: Alta | J12: En Proceso | K12: 2.5
B13: REQ003 | C13: Registrar Producto | D13: Propietario | E13: Ingresar datos del producto en formulario, el sistema genera código automático y valida información antes de guardar | F13: Ingresar datos del producto en formulario, el sistema genera código automático y valida información antes de guardar | G13: Leonardo Narvaez | H13: Códigos de producto no se reutilizan al eliminar | I13: Alta | J13: En Proceso | K13: =SUM(K14:K17) -> 10.5
B14: REQ003-1 | C14: Formulario de registro de producto | E14: Ingresar datos del producto mediante un formulario | F14: Capturar correctamente la información | G14: Leonardo Narvaez | H14: Campos obligatorios | I14: Alta | J14: En Proceso | K14: 3.5
B15: REQ003-2 | C15: Generación automática de código | E15: Generar un código único automático | F15: Evitar duplicación de productos | G15: Leonardo Narvaez | H15: Formato letra+dígitos | I15: Alta | J15: En Proceso | K15: 2
B16: REQ003-3 | C16: Validación de datos de registro | E16: Validar la información antes de guardar | F16: Prevenir registros incorrectos | G16: Leonardo Narvaez | H16: No permitir campos vacíos | I16: Alta | J16: En Proceso | K16: 3
B17: REQ003-4 | C17: Almacenamiento en base de datos | E17: Guardar el producto en la base de datos | F17: Persistir la información correctamente | G17: Leonardo Narvaez | H17: Usar transacción segura | I17: Alta | J17: En Proceso | K17: 2

Sheet sprint1
B3: ID | C3: Tema | D3: Como un.. | E3: Necesito | F3: Así podré... | G3: Encargado | H3: Notas | I3: Prioridad | J3: Status | K3: HORAS
B4: REQ004 | C4: Eliminar Producto | D4: Propietario | E4: Seleccionar producto, confirmar eliminación, sistema actualiza estado a Inactivo | F4: Seleccionar producto, confirmar eliminación, sistema actualiza estado a Inactivo | H4: Código de producto no se libera para reutilización | I4: Alta | J4: En Proceso | K4: 7
B5: REQ004-1 | C5: Interfaz de confirmación | E5: Crear un modal o alerta de confirmación antes de eliminar | F5: Evitar eliminaciones accidentales | H5: Usar estilos de advertencia (rojo) | I5: Alta | J5: En Proceso | K5: 2
B6: REQ004-2 | C6: Actualización de estado (Lógica) | E6: Cambiar el atributo 'estado' a 'Inactivo' en la base de datos | F6: Mantener integridad referencial sin borrar físicamente | H6: Implementar "Soft Delete" | I6: Alta | J6: En Proceso | K6: 2.5
B7: REQ004-3 | C7: Refresco de lista | E7: Actualizar la vista de productos excluyendo los inactivos | F7: Visualizar solo productos vigentes | H7: Optimizar consulta SQL | I7: Alta | J7: En Proceso | K7: 2.5
B8: REQ005 | C8: Registrar Pedido | D8: Propietario | E8: Seleccionar cliente y productos, especificar cantidades, sistema calcula totales y guarda pedido | F8: Seleccionar cliente y productos, especificar cantidades, sistema calcula totales y guarda pedido | H8: Fecha auto-completada con fecha actual pero editable | I8: Alta | J8: En Proceso | K8: 12
B9: REQ005-1 | C9: Cabecera del pedido | E9: Diseñar formulario con selección de cliente y fecha | F9: Identificar el origen y momento de la venta | H9: Picker de fecha funcional | I9: Alta | J9: En Proceso | K9: 3
B10: REQ005-2 | C10: Detalle de artículos | E10: Implementar selector de productos y entrada de cantidades | F10: Armar el carrito de compra | H10: Validar que cantidad > 0 | I10: Alta | J10: En Proceso | K10: 4
B11: REQ005-3 | C11: Cálculo de totales | E11: Programar lógica de subtotal, impuestos y total general | F11: Informar el costo final en tiempo real | H11: Cálculos automáticos al cambiar cantidad | I11: Alta | J11: En Proceso | K11: 2
B12: REQ005-4 | C12: Persistencia y Stock | E12: Guardar pedido y descontar cantidades del inventario | F12: Mantener el stock actualizado y registro de venta | H12: Usar transacciones ACID | I12: Alta | J12: En Proceso | K12: 3
B13: REQ006 | C13: Consultar Pedido | D13: Propietario | E13: Aplicar filtros (ID, cliente, fechas, estado), sistema muestra resultados | F13: Aplicar filtros (ID, cliente, fechas, estado), sistema muestra resultados | H13: Interfaz intuitiva para filtrado | I13: Media | J13: En Proceso | K13: 8
B14: REQ006-1 | C14: Panel de filtros | E14: Construir controles de búsqueda por múltiples criterios | F14: Localizar pedidos específicos rápidamente | H14: Filtros combinables | I14: Alta | J14: En Proceso | K14: 3
B15: REQ006-2 | C15: Grilla de resultados | E15: Visualizar lista de pedidos con información resumida | F15: Tener un panorama general de las ventas | H15: Incluir paginación | I15: Alta | J15: En Proceso | K15: 3
B16: REQ006-3 | C16: Vista de detalle | E16: Permitir ver el detalle completo de un pedido seleccionado | F16: Revisar los artículos incluidos en una venta | H16: Solo lectura | I16: Alta | J16: En Proceso | K16: 2
B17: REQ007 | C17: Eliminar Pedido | D17: Propietario | E17: Seleccionar pedido, confirmar eliminación, actualizar estado a Cancelado y revertir stock | F17: Seleccionar pedido, confirmar eliminación, actualizar estado a Cancelado y revertir stock | H17: Eliminación lógica que conserva historial | I17: Alta | J17: En Proceso | K17: 7.5
B18: REQ007-1 | C18: Lógica de cancelación | E18: Cambiar estatus de pedido a 'Cancelado' | F18: Invalidar la venta sin borrar el registro | H18: Validar que no esté ya cancelado | I18: Alta | J18: En Proceso | K18: 2.5
B19: REQ007-2 | C19: Reversión de Inventario | E19: Devolver las cantidades de productos al stock disponible | F19: Mantener la coherencia del almacén | H19: Lógica inversa al REQ005-4 | I19: Alta | J19: En Proceso | K19: 3
B20: REQ007-3 | C20: Auditoría de cambios | E20: Registrar quién y cuándo canceló el pedido | F20: Tener trazabilidad de movimientos sensibles | H20: Guardar en tabla de logs | I20: Alta | J20: En Proceso | K20: 2

Sheet sprint2
B3: ID | C3: Tema | D3: Como un.. | E3: Necesito | F3: Así podré... | G3: Encargado | H3: Notas | I3: Prioridad | J3: Status | K3: HORAS
B4: REQ008 | C4: Consultar Cliente | D4: Propietario | E4: Ingresar criterio de búsqueda, sistema muestra resultados coincidentes | F4: Ingresar criterio de búsqueda, sistema muestra resultados coincidentes | H4: Implementar búsqueda por nombre o DNI | I4: Media | J4: En Proceso | K4: 7
B5: REQ008-1 | C5: Interfaz de búsqueda | E5: Crear barra de búsqueda y filtros de estado | F5: Localizar clientes rápidamente | H5: Diseño responsivo | I5: Media | J5: En Proceso | K5: 2.5
B6: REQ008-2 | C6: Lógica de filtrado | E6: Programar consultas SQL con operadores LIKE | F6: Obtener coincidencias parciales | H6: Optimizar índices de búsqueda | I6: Media | J6: En Proceso | K6: 2.5
B7: REQ008-3 | C7: Visualización de lista | E7: Diseñar tabla de resultados con acciones (Editar/Borrar) | F7: Gestionar la cartera de clientes | H7: Incluir scroll infinito o paginación | I7: Media | J7: En Proceso | K7: 2
B8: REQ009 | C8: Registrar Cliente | D8: Propietario | E8: Ingresar datos en formulario, validar formatos y guardar | F8: Ingresar datos en formulario, validar formatos y guardar en base de datos | H8: Todos los campos son obligatorios | I8: Alta | J8: En Proceso | K8: 9
B9: REQ009-1 | C9: Formulario de registro | E9: Diseñar campos de texto para datos personales | F9: Capturar la información del cliente | H9: Validar campos obligatorios | I9: Alta | J9: En Proceso | K9: 3
B10: REQ009-2 | C10: Validación de formatos | E10: Implementar máscaras (teléfono, email, DNI) | F10: Asegurar la calidad de los datos | H10: Usar expresiones regulares | I10: Alta | J10: En Proceso | K10: 3
B11: REQ009-3 | C11: Persistencia de datos | E11: Crear función de guardado en la tabla Clientes | F11: Almacenar nuevos clientes permanentemente | H11: Validar DNI duplicado | I11: Alta | J11: En Proceso | K11: 3
B12: REQ010 | C12: Actualizar Cliente | D12: Propietario | E12: Seleccionar cliente de lista, editar campos y guardar cambios | F12: Seleccionar cliente de lista, editar campos y guardar cambios validados | I12: Alta | J12: En Proceso | K12: 8.5
B13: REQ010-1 | C13: Carga de datos | E13: Programar la recuperación de datos al seleccionar cliente | F13: Editar información existente sin reescribir todo | H13: Pre-cargar el formulario | I13: Alta | J13: En Proceso | K13: 2.5
B14: REQ010-2 | C14: Edición y Validación | E14: Permitir modificar campos manteniendo reglas de negocio | F14: Mantener la información actualizada | H14: Bloquear edición de ID único | I14: Alta | J14: En Proceso | K14: 3
B15: REQ010-3 | C15: Actualización en BD | E15: Ejecutar el comando UPDATE con los nuevos valores | F15: Reflejar los cambios en el sistema | H15: Usar transacciones seguras | I15: Alta | J15: En Proceso | K15: 3
B16: REQ011 | C16: Eliminar Cliente | D16: Propietario | E16: Seleccionar cliente, confirmar eliminación, actualizar estado a Inactivo | F16: Seleccionar cliente, confirmar eliminación, actualizar estado a Inactivo | H16: Alternar vista entre Activos e Inactivos | I16: Media | J16: En Proceso | K16: 7.5
B17: REQ011-1 | C17: Confirmación de baja | E17: Crear diálogo de confirmación de eliminación | F17: Prevenir bajas accidentales | H17: Estilo visual de alerta | I17: Media | J17: En Proceso | K17: 2
B18: REQ011-2 | C18: Baja Lógica | E18: Cambiar estado del cliente a 'Inactivo' | F18: Deshabilitar sin perder el historial de pedidos | H18: No borrar físicamente | I18: Alta | J18: En Proceso | K18: 2.5
B19: REQ011-3 | C19: Switch de visualización | E19: Implementar filtro para ver clientes activos vs. inactivos | F19: Gestionar clientes antiguos o suspendidos | H19: Toggle de visualización | I19: Media | J19: En Proceso | K19: 3

Sheet sprint3
B3: ID | C3: Tema | D3: Como un.. | E3: Necesito | F3: Así podré... | G3: Encargado | H3: Notas | I3: Prioridad | J3: Status | K3: HORAS
B4: REQ012 | C4: Actualizar Pedido | D4: Propietario | E4: Seleccionar pedido, editar datos, sistema recalcula totales y actualiza inventario | F4: Seleccionar pedido, editar datos, sistema recalcula totales y actualiza inventario | H4: Ajusta inventario por aumentos o disminuciones | I4: Media | J4: En Proceso | K4: 10
B5: REQ012-1 | C5: Interfaz de edición | E5: Habilitar edición en el formulario de pedido existente | F5: Modificar cantidades o productos erróneos | H5: Cargar datos actuales | I5: Alta | J5: En Proceso | K5: 3
B6: REQ012-2 | C6: Lógica de ajuste de Stock | E6: Calcular la diferencia entre cantidad vieja y nueva para ajustar inventario | F6: Mantener el stock real sincronizado | H6: Manejar saldos negativos | I6: Alta | J6: En Proceso | K6: 4
B7: REQ012-3 | C7: Recálculo de Totales | E7: Actualizar dinámicamente el precio total del pedido | F7: Reflejar el nuevo costo tras la edición | H7: Validar precios vigentes | I7: Alta | J7: En Proceso | K7: 3
B8: REQ013 | C8: Controlar Estado | D8: Propietario | E8: Seleccionar pedido, elegir nuevo estado de opciones permitidas, actualizar | F8: Seleccionar pedido, elegir nuevo estado de opciones permitidas, actualizar | H8: Estados: Pendiente, En Proceso, En Espera, Completado, Cancelado | I8: Alta | J8: En Proceso | K8: 6
B9: REQ013-1 | C9: Selector de estados | E9: Implementar un dropdown con los estados permitidos | F9: Cambiar la etapa logística del pedido | H9: Solo estados definidos | I9: Alta | J9: En Proceso | K9: 2
B10: REQ013-2 | C10: Máquina de estados | E10: Validar que el cambio de estado sea lógico (ej. de Pendiente a Completado) | F10: Evitar saltos de proceso incorrectos | H10: Reglas de negocio | I10: Media | J10: En Proceso | K10: 2
B11: REQ013-3 | C11: Actualización de estatus | E11: Persistir el nuevo estado en la base de datos | F11: Informar el progreso en tiempo real | H11: Actualizar fecha de cambio | I11: Alta | J11: En Proceso | K11: 2
B12: REQ014 | C12: Generar Reporte | D12: Propietario | E12: Aplicar filtros deseados, generar reporte, descargar archivo Excel con información completa | F12: Aplicar filtros deseados, generar reporte, descargar archivo Excel con información completa | H12: Incluye agregados como total de ventas y productos vendidos | I12: Media | J12: En Proceso | K12: 9
B13: REQ014-1 | C13: Motor de filtrado | E13: Crear interfaz para seleccionar rango de fechas y categorías | F13: Extraer datos específicos para el reporte | H13: Filtros por cliente/producto | I13: Media | J13: En Proceso | K13: 3
B14: REQ014-2 | C14: Lógica de agregación | E14: Calcular sumatorias de ventas y conteo de productos | F14: Obtener indicadores clave de rendimiento | H14: Agrupar por categorías | I14: Alta | J14: En Proceso | K14: 3
B15: REQ014-3 | C15: Exportación a Excel | E15: Implementar librería para generar y descargar el archivo .xlsx | F15: Analizar datos fuera del sistema | H15: Formato de tabla limpia | I15: Media | J15: En Proceso | K15: 3
B16: REQ015 | C16: Mezcla Personalizada | D16: Propietario | E16: Seleccionar productos, ingresar cantidades en libras, sistema calcula precio dinámicamente | F16: Seleccionar productos, ingresar cantidades en libras, sistema calcula precio dinámicamente | H16: Nombre: 3-25 caracteres alfanuméricos | I16: Baja | J16: En Proceso | K16: 8
B17: REQ015-1 | C17: Creador de mezclas | E17: Diseñar interfaz para combinar múltiples productos por peso | F17: Crear productos únicos a solicitud del cliente | H17: Validar nombre (3-25 char) | I17: Media | J17: En Proceso | K17: 3
B18: REQ015-2 | C18: Algoritmo de costos | E18: Programar cálculo de precio basado en el costo por libra de cada componente | F18: Asignar un precio justo a la mezcla | H18: Conversión de unidades | I18: Media | J18: En Proceso | K18: 3
B19: REQ015-3 | C19: Guardado de receta | E19: Almacenar la composición de la mezcla personalizada | F19: Reutilizar la mezcla en futuros pedidos | H19: Tabla de composición | I19: Baja | J19: En Proceso | K19: 2

Sheet sprint4
B3: ID | C3: Tema | D3: Como un.. | E3: Necesito | F3: Así podré... | G3: Encargado | H3: Notas | I3: Prioridad | J3: Status | K3: HORAS
B4: REQ016 | C4: Consultar Mezclas | D4: Propietario | E4: Ver mezclas predefinidas y guardadas, recibir sugerencias, ajustar cantidades | F4: Ver mezclas predefinidas y guardadas, recibir sugerencias, ajustar cantidades | H4: Recomendaciones basadas en compras frecuentes | I4: Alta | J4: En Proceso | K4: 10
B5: REQ016-1 | C5: Interfaz de catálogo | E5: Diseñar pantalla para visualizar tarjetas de mezclas guardadas | F5: Explorar opciones de mezclas rápidamente | H5: Incluir miniaturas visuales | I5: Alta | J5: En Proceso | K5: 3
B6: REQ016-2 | C6: Motor de sugerencias | E6: Implementar algoritmo que analice pedidos pasados para sugerir mezclas | F6: Ofrecer opciones personalizadas al cliente | H6: Basado en historial del cliente | I6: Alta | J6: En Proceso | K6: 4
B7: REQ016-3 | C7: Ajuste dinámico | E7: Permitir modificar cantidades de la mezcla antes de agregar al pedido | F7: Personalizar la mezcla final en tiempo real | H7: Recalcular precio al instante | I7: Media | J7: En Proceso | K7: 3
B8: REQ017 | C8: Guardar Mezcla | D8: Propietario | E8: Diseñar mezcla, ingresar nombre único, guardar en perfil | F8: Diseñar mezcla, ingresar nombre único, guardar en perfil | H8: Mezclas guardadas no afectan stock hasta usarse en pedido | I8: Media | J8: En Proceso | K8: 8.5
B9: REQ017-1 | C9: Formulario de creación | E9: Crear vista para asignar componentes y nombre único (3-25 caracteres) | F9: Definir nuevas recetas propias | H9: Validar nombre único | I9: Media | J9: En Proceso | K9: 3
B10: REQ017-2 | C10: Persistencia de Perfil | E10: Guardar la estructura de la mezcla vinculada al perfil del propietario | F10: Recuperar mezclas en sesiones futuras | H10: Guardar en tabla 'Mezclas_Perfil' | I10: Alta | J10: En Proceso | K10: 3
B11: REQ017-3 | C11: Validación de Stock | E11: Verificar disponibilidad de ingredientes solo al intentar añadir al pedido | F11: Evitar que una receta guardada bloquee inventario | H11: Notificar si falta un componente | I11: Media | J11: En Proceso | K11: 2.5

Sheet sprint final
B3: ID | C3: Tema | D3: Como un.. | E3: Necesito | F3: Así podré... | G3: Encargado | H3: Notas | I3: Prioridad | J3: Status | K3: HORAS
B4: REQ001 | C4: Consultar Producto | D4: Propietario | E4: Ingresar criterio de búsqueda (nombre o código), sistema muestra resultados coincidentes | F4: Ingresar criterio de búsqueda (nombre o código), sistema muestra resultados coincidentes | G4: AnthonyMorales / Jordan Guaman | H4: Búsqueda por código prioritaria si tiene formato letra+dígitos | I4: Baja | J4: En Proceso | K4: =SUM(K5:K7) -> 14
B5: REQ001-1 | C5: Diseño del modelo de datos | E5: Definir la estructura de las tablas, campos, relaciones y restricciones del sistema. | F5: Asegurar que la información se almacene de forma correcta y escalable. | G5: Jordan Guaman | H5: Incluir entidades de productos, categorías y relaciones básicas. Validar normalización. | I5: Alta | J5: En Proceso | K5: 5
B6: REQ001-2 | C6: Implementación de la base de datos en SQLite | E6: Crear físicamente la base de datos usando el modelo definido. | F6: Guardar y consultar datos reales desde la aplicación. | G6: AnthonyMorales | H6: Usar SQLite por ser liviano y portable. Crear scripts de creación. | I6: Alta | J6: En Proceso | K6: 4
B7: REQ001-3 | C7: Desarrollo de la interfaz de listado de productos | E7: Construir una pantalla donde se visualicen los productos. | F7: Mostrar información al usuario de forma clara e interactiva. | G7: AnthonyMorales | H7: Incluir scroll y busqueda | I7: Alta | J7: En Proceso | K7: 5
B8: REQ002 | C8: Actualizar Producto | D8: Propietario | E8: Seleccionar producto de lista, editar campos en formulario y guardar cambios validados | F8: Seleccionar producto de lista, editar campos en formulario y guardar cambios validados | G8: Caetano Flores | H8: Permite incrementos y decrementos de stock con validaciones | I8: Alta | J8: En Proceso | K8: =SUM(K9:K12) -> 10.5
B9: REQ002-1 | C9: Selección de producto desde la lista | E9: Seleccionar un producto desde el listado | F9: Identificar correctamente el producto a modificar | G9: Caetano Flores | H9: Resaltar producto seleccionado | I9: Alta | J9: En Proceso | K9: 2
B10: REQ002-2 | C10: Formulario de edición de producto | E10: Mostrar los datos del producto en un formulario editable | F10: Modificar la información de forma controlada | G10: Caetano Flores | H10: Bloquear edición del código | I10: Alta | J10: En Proceso | K10: 3.5
B11: REQ002-3 | C11: Validación de datos de edición | E11: Validar campos antes de guardar cambios | F11: Evitar errores e inconsistencias | G11: Caetano Flores | H11: Stock no negativo, campos obligatorios | I11: Alta | J11: En Proceso | K11: 2.5
B12: REQ002-4 | C12: Actualización en base de datos | E12: Guardar los cambios del producto editado | F12: Mantener la base de datos actualizada | G12: Caetano Flores | H12: Usar transacciones | I12: Alta | J12: En Proceso | K12: 2.5
B13: REQ003 | C13: Registrar Producto | D13: Propietario | E13: Ingresar datos del producto en formulario, el sistema genera código automático y valida información antes de guardar | F13: Ingresar datos del producto en formulario, el sistema genera código automático y valida información antes de guardar | G13: Leonardo Narvaez | H13: Códigos de producto no se reutilizan al eliminar | I13: Alta | J13: En Proceso | K13: =SUM(K14:K17) -> 10.5
B14: REQ003-1 | C14: Formulario de registro de producto | E14: Ingresar datos del producto mediante un formulario | F14: Capturar correctamente la información | G14: Leonardo Narvaez | H14: Campos obligatorios | I14: Alta | J14: En Proceso | K14: 3.5
B15: REQ003-2 | C15: Generación automática de código | E15: Generar un código único automático | F15: Evitar duplicación de productos | G15: Leonardo Narvaez | H15: Formato letra+dígitos | I15: Alta | J15: En Proceso | K15: 2
B16: REQ003-3 | C16: Validación de datos de registro | E16: Validar la información antes de guardar | F16: Prevenir registros incorrectos | G16: Leonardo Narvaez | H16: No permitir campos vacíos | I16: Alta | J16: En Proceso | K16: 3
B17: REQ003-4 | C17: Almacenamiento en base de datos | E17: Guardar el producto en la base de datos | F17: Persistir la información correctamente | G17: Leonardo Narvaez | H17: Usar transacción segura | I17: Alta | J17: En Proceso | K17: 2
B18: REQ004 | C18: Eliminar Producto | D18: Propietario | E18: Seleccionar producto, confirmar eliminación, sistema actualiza estado a Inactivo | F18: Seleccionar producto, confirmar eliminación, sistema actualiza estado a Inactivo | H18: Código de producto no se libera para reutilización | I18: Alta | J18: En Proceso | K18: 7
B19: REQ004-1 | C19: Interfaz de confirmación | E19: Crear un modal o alerta de confirmación antes de eliminar | F19: Evitar eliminaciones accidentales | H19: Usar estilos de advertencia (rojo) | I19: Alta | J19: En Proceso | K19: 2
B20: REQ004-2 | C20: Actualización de estado (Lógica) | E20: Cambiar el atributo 'estado' a 'Inactivo' en la base de datos | F20: Mantener integridad referencial sin borrar físicamente | H20: Implementar "Soft Delete" | I20: Alta | J20: En Proceso | K20: 2.5
B21: REQ004-3 | C21: Refresco de lista | E21: Actualizar la vista de productos excluyendo los inactivos | F21: Visualizar solo productos vigentes | H21: Optimizar consulta SQL | I21: Alta | J21: En Proceso | K21: 2.5
B22: REQ005 | C22: Registrar Pedido | D22: Propietario | E22: Seleccionar cliente y productos, especificar cantidades, sistema calcula totales y guarda pedido | F22: Seleccionar cliente y productos, especificar cantidades, sistema calcula totales y guarda pedido | H22: Fecha auto-completada con fecha actual pero editable | I22: Alta | J22: En Proceso | K22: 12
B23: REQ005-1 | C23: Cabecera del pedido | E23: Diseñar formulario con selección de cliente y fecha | F23: Identificar el origen y momento de la venta | H23: Picker de fecha funcional | I23: Alta | J23: En Proceso | K23: 3
B24: REQ005-2 | C24: Detalle de artículos | E24: Implementar selector de productos y entrada de cantidades | F24: Armar el carrito de compra | H24: Validar que cantidad > 0 | I24: Alta | J24: En Proceso | K24: 4
B25: REQ005-3 | C25: Cálculo de totales | E25: Programar lógica de subtotal, impuestos y total general | F25: Informar el costo final en tiempo real | H25: Cálculos automáticos al cambiar cantidad | I25: Alta | J25: En Proceso | K25: 2
B26: REQ005-4 | C26: Persistencia y Stock | E26: Guardar pedido y descontar cantidades del inventario | F26: Mantener el stock actualizado y registro de venta | H26: Usar transacciones ACID | I26: Alta | J26: En Proceso | K26: 3
B27: REQ006 | C27: Consultar Pedido | D27: Propietario | E27: Aplicar filtros (ID, cliente, fechas, estado), sistema muestra resultados | F27: Aplicar filtros (ID, cliente, fechas, estado), sistema muestra resultados | H27: Interfaz intuitiva para filtrado | I27: Media | J27: En Proceso | K27: 8
B28: REQ006-1 | C28: Panel de filtros | E28: Construir controles de búsqueda por múltiples criterios | F28: Localizar pedidos específicos rápidamente | H28: Filtros combinables | I28: Alta | J28: En Proceso | K28: 3
B29: REQ006-2 | C29: Grilla de resultados | E29: Visualizar lista de pedidos con información resumida | F29: Tener un panorama general de las ventas | H29: Incluir paginación | I29: Alta | J29: En Proceso | K29: 3
B30: REQ006-3 | C30: Vista de detalle | E30: Permitir ver el detalle completo de un pedido seleccionado | F30: Revisar los artículos incluidos en una venta | H30: Solo lectura | I30: Alta | J30: En Proceso | K30: 2
B31: REQ007 | C31: Eliminar Pedido | D31: Propietario | E31: Seleccionar pedido, confirmar eliminación, actualizar estado a Cancelado y revertir stock | F31: Seleccionar pedido, confirmar eliminación, actualizar estado a Cancelado y revertir stock | H31: Eliminación lógica que conserva historial | I31: Alta | J31: En Proceso | K31: 7.5
B32: REQ007-1 | C32: Lógica de cancelación | E32: Cambiar estatus de pedido a 'Cancelado' | F32: Invalidar la venta sin borrar el registro | H32: Validar que no esté ya cancelado | I32: Alta | J32: En Proceso | K32: 2.5
B33: REQ007-2 | C33: Reversión de Inventario | E33: Devolver las cantidades de productos al stock disponible | F33: Mantener la coherencia del almacén | H33: Lógica inversa al REQ005-4 | I33: Alta | J33: En Proceso | K33: 3
B34: REQ007-3 | C34: Auditoría de cambios | E34: Registrar quién y cuándo canceló el pedido | F34: Tener trazabilidad de movimientos sensibles | H34: Guardar en tabla de logs | I34: Alta | J34: En Proceso | K34: 2
B35: REQ008 | C35: Consultar Cliente | D35: Propietario | E35: Ingresar criterio de búsqueda, sistema muestra resultados coincidentes | F35: Ingresar criterio de búsqueda, sistema muestra resultados coincidentes | H35: Implementar búsqueda por nombre o DNI | I35: Media | J35: En Proceso | K35: 7
B36: REQ008-1 | C36: Interfaz de búsqueda | E36: Crear barra de búsqueda y filtros de estado | F36: Localizar clientes rápidamente | H36: Diseño responsivo | I36: Media | J36: En Proceso | K36: 2.5
B37: REQ008-2 | C37: Lógica de filtrado | E37: Programar consultas SQL con operadores LIKE | F37: Obtener coincidencias parciales | H37: Optimizar índices de búsqueda | I37: Media | J37: En Proceso | K37: 2.5
B38: REQ008-3 | C38: Visualización de lista | E38: Diseñar tabla de resultados con acciones (Editar/Borrar) | F38: Gestionar la cartera de clientes | H38: Incluir scroll infinito o paginación | I38: Media | J38: En Proceso | K38: 2
B39: REQ009 | C39: Registrar Cliente | D39: Propietario | E39: Ingresar datos en formulario, validar formatos y guardar | F39: Ingresar datos en formulario, validar formatos y guardar en base de datos | H39: Todos los campos son obligatorios | I39: Alta | J39: En Proceso | K39: 9
B40: REQ009-1 | C40: Formulario de registro | E40: Diseñar campos de texto para datos personales | F40: Capturar la información del cliente | H40: Validar campos obligatorios | I40: Alta | J40: En Proceso | K40: 3
B41: REQ009-2 | C41: Validación de formatos | E41: Implementar máscaras (teléfono, email, DNI) | F41: Asegurar la calidad de los datos | H41: Usar expresiones regulares | I41: Alta | J41: En Proceso | K41: 3
B42: REQ009-3 | C42: Persistencia de datos | E42: Crear función de guardado en la tabla Clientes | F42: Almacenar nuevos clientes permanentemente | H42: Validar DNI duplicado | I42: Alta | J42: En Proceso | K42: 3
...

Sheet burdonchart
B1: SPRINT 0
C3: Estimado | D3: Dia 5 | E3: Dia 4 | F3: Dia 3 | G3: Dia 2 | H3: Dia 1 | I3: Total de Horas
B4: REQ001-1 | C4: =VLOOKUP(B4, sprint0!$B$4:$K$17, 10) -> 5 | D4: 5 | E4: 0 | F4: 0 | G4: 0 | H4: 0 | I4: =SUM(D4:H4) -> 5
B5: REQ001-2 | C5: =VLOOKUP(B5, sprint0!$B$4:$K$17, 10) -> 4 | D5: 0 | E5: 3 | F5: 1 | G5: 0 | H5: 0 | I5: =SUM(D5:H5) -> 4
B6: REQ001-3 | C6: =VLOOKUP(B6, sprint0!$B$4:$K$17, 10) -> 5 | D6: 0 | E6: 1 | F6: 4 | G6: 0 | H6: 0 | I6: =SUM(D6:H6) -> 5
B7: REQ002-1 | C7: =VLOOKUP(B7, sprint0!$B$4:$K$17, 10) -> 2 | D7: 2 | E7: 0 | F7: 0 | G7: 0 | H7: 0 | I7: =SUM(D7:H7) -> 2
B8: REQ002-2 | C8: =VLOOKUP(B8, sprint0!$B$4:$K$17, 10) -> 3.5 | D8: 0 | E8: 3.5 | F8: 0 | G8: 0 | H8: 0 | I8: =SUM(D8:H8) -> 3.5
B9: REQ002-3 | C9: =VLOOKUP(B9, sprint0!$B$4:$K$17, 10) -> 2.5 | D9: 0 | E9: 0 | F9: 2.5 | G9: 0 | H9: 0 | I9: =SUM(D9:H9) -> 2.5
B10: REQ002-4 | C10: =VLOOKUP(B10, sprint0!$B$4:$K$17, 10) -> 2.5 | D10: 0 | E10: 0 | F10: 0 | G10: 1.5 | H10: 1 | I10: =SUM(D10:H10) -> 2.5
B11: REQ003-1 | C11: =VLOOKUP(B11, sprint0!$B$4:$K$17, 10) -> 3.5 | D11: 3.5 | E11: 0 | F11: 0 | G11: 0 | H11: 0 | I11: =SUM(D11:H11) -> 3.5
B12: REQ003-2 | C12: =VLOOKUP(B12, sprint0!$B$4:$K$17, 10) -> 2 | D12: 0 | E12: 2 | F12: 0 | G12: 0 | H12: 0 | I12: =SUM(D12:H12) -> 2
B13: REQ003-3 | C13: =VLOOKUP(B13, sprint0!$B$4:$K$17, 10) -> 3 | D13: 0 | E13: 0 | F13: 1 | G13: 2 | H13: 0 | I13: =SUM(D13:H13) -> 3
B14: REQ003-4 | C14: =VLOOKUP(B14, sprint0!$B$4:$K$17, 10) -> 2 | D14: 0 | E14: 0 | F14: 0 | G14: 0 | H14: 2 | I14: =SUM(D14:H14) -> 2
B19: Horas Estimadas | C19: =SUM(C4:C14) -> 35 | D19: =C19-SUM(D4:D14) -> 24.5 | E19: =D19-SUM(E4:E14) -> 15 | F19: =E19-SUM(F4:F14) -> 6.5 | G19: =F19-SUM(G4:G14) -> 3 | H19: =G19-SUM(H4:H14) -> 0
B20: Horas Estimadas Restantes | C20: =SUM(C4:C14) -> 35 | D20: =C20-(SUM(C4:C14)/5) -> 28 | E20: =D20-(SUM(C4:C14)/5) -> 21 | F20: =E20-(SUM(C4:C14)/5) -> 14 | G20: =F20-(SUM(C4:C14)/5) -> 7 | H20: =G20-(SUM(C4:C14)/5) -> 0
B24: El Sprint concluyó con un resultado altamente exitoso y una predictibilidad excepcional, ya que el equipo logró completar el 100% de las 35 Horas Estimadas dentro de los 7 días planificados, alcanzando la meta de 0 horas restantes. El equipo mantuvo un ritmo de progreso notablemente uniforme, completando un promedio constante de 7 horas de esfuerzo por día, lo cual se refleja en que la línea de progreso real en el Burndown Chart se mantuvo consistentemente alineada con la línea ideal, indicando un flujo de trabajo estable, libre de estancamientos o sobrecargas tardías, y sirviendo este Sprint como un modelo de rendimiento óptimo para la calibración futura de la capacidad.
B42: SPRINT 1
B44: ID | C44: Estimado | D44: Día 1 | E44: Día 2 | F44: Día 3 | G44: Día 4 | H44: Día 5 | I44: Total Horas
B45: REQ004-1 | C45: 2 | D45: 2 | E45: 0 | F45: 0 | G45: 0 | H45: 0 | I45: 2
B46: REQ004-2 | C46: 2.5 | D46: 0 | E46: 2.5 | F46: 0 | G46: 0 | H46: 0 | I46: 2.5
B47: REQ004-3 | C47: 2.5 | D47: 0 | E47: 0 | F47: 2.5 | G47: 0 | H47: 0 | I47: 2.5
B48: REQ005-1 | C48: 3 | D48: 3 | E48: 0 | F48: 0 | G48: 0 | H48: 0 | I48: 3
B49: REQ005-2 | C49: 4 | D49: 0 | E49: 4 | F49: 0 | G49: 0 | H49: 0 | I49: 4
B50: REQ005-3 | C50: 2 | D50: 0 | E50: 0 | F50: 2 | G50: 0 | H50: 0 | I50: 2
B51: REQ005-4 | C51: 3 | D51: 0 | E51: 0 | F51: 0 | G51: 3 | H51: 0 | I51: 3
B52: REQ006-1 | C52: 3 | D52: 0 | E52: 0 | F52: 3 | G52: 0 | H52: 0 | I52: 3
B53: REQ006-2 | C53: 3 | D53: 0 | E53: 0 | F53: 0 | G53: 3 | H53: 0 | I53: 3
B54: REQ006-3 | C54: 2 | D54: 0 | E54: 0 | F54: 0 | G54: 0 | H54: 2 | I54: 2
B55: REQ007-1 | C55: 2.5 | D55: 0 | E55: 0 | F55: 0 | G55: 0 | H55: 2.5 | I55: 2.5
B56: REQ007-2 | C56: 3 | D56: 0 | E56: 0 | F56: 0 | G56: 0 | H56: 3 | I56: 3
B57: REQ007-3 | C57: 2 | D57: 0 | E57: 0 | F57: 0 | G57: 0 | H57: 2 | I57: 2
B60: Horas Estimadas | C60: =SUM(C45:C57) -> 34.5 | D60: =C60-SUM(D45:D57) -> 29.5 | E60: =D60-SUM(E45:E57) -> 23 | F60: =E60-SUM(F45:F57) -> 15.5 | G60: =F60-SUM(G45:G57) -> 9.5 | H60: =G60-SUM(H45:H57) -> 0
B61: Horas Estimadas Restantes | C61: =SUM(C45:C57) -> 34.5 | D61: =C61-(SUM(C45:C57)/5) -> 27.6 | E61: =D61-(SUM(C45:C57)/5) -> 20.7 | F61: =E61-(SUM(C45:C57)/5) -> 13.8 | G61: =F61-(SUM(C45:C57)/5) -> 6.9 | H61: =G61-(SUM(C45:C57)/5) -> 0
B83: SPRINT 2
B85: ID | C85: Estimado | D85: Día 1 | E85: Día 2 | F85: Día 3 | G85: Día 4 | H85: Día 5 | I85: Total Horas
B86: REQ008-1 | C86: 2.5 | D86: 2.5 | E86: 0 | F86: 0 | G86: 0 | H86: 0 | I86: 2.5
B87: REQ008-2 | C87: 2.5 | D87: 0 | E87: 2.5 | F87: 0 | G87: 0 | H87: 0 | I87: 2.5
B88: REQ008-3 | C88: 2 | D88: 0 | E88: 0 | F88: 2 | G88: 0 | H88: 0 | I88: 2
B89: REQ009-1 | C89: 3 | D89: 3 | E89: 0 | F89: 0 | G89: 0 | H89: 0 | I89: 3
B90: REQ009-2 | C90: 3 | D90: 0 | E90: 3 | F90: 0 | G90: 0 | H90: 0 | I90: 3
...
